[2023-03-25 04:03:12,660][haystack.modeling.utils][INFO] - Using devices: CPU - Number of GPUs: 0
[2023-03-25 04:03:12,660][haystack.utils.import_utils][INFO] - Fetching from https://s3.eu-central-1.amazonaws.com/deepset.ai-farm-qa/datasets/documents/wiki_gameofthrones_txt1.zip to 'data/build_your_first_question_answering_system'
[2023-03-25 04:03:13,832][haystack.pipelines.base][INFO] - It seems that an indexing Pipeline is run, so using the nodes' run method instead of run_batch.
[2023-03-25 04:03:14,203][haystack.nodes.preprocessor.preprocessor][WARNING] - We found one or more sentences whose word count is higher than the split length.
[2023-03-25 04:03:14,236][haystack.nodes.preprocessor.preprocessor][WARNING] - Document b48fb0da693eb4d81b3566d0069868b3 is 10488 characters long after preprocessing, where the maximum length should be 10000. Something might be wrong with the splitting, check the document affected to prevent issues at query time.
[2023-03-25 04:03:14,377][haystack.nodes.preprocessor.preprocessor][WARNING] - Document dd048b8e5bcb7de1be5bd3937f15442f is 14232 characters long after preprocessing, where the maximum length should be 10000. Something might be wrong with the splitting, check the document affected to prevent issues at query time.
[2023-03-25 04:03:14,426][haystack.nodes.preprocessor.preprocessor][WARNING] - Document 4189b42892b3d941c035947d512b69dd is 12059 characters long after preprocessing, where the maximum length should be 10000. Something might be wrong with the splitting, check the document affected to prevent issues at query time.
[2023-03-25 04:03:15,228][haystack.modeling.utils][INFO] - Using devices: CPU - Number of GPUs: 0
[2023-03-25 04:08:36,880][root][ERROR] - got unexpected error processing a message: invalid interface name: editai.
Traceback (most recent call last):
  File "/home/sami/.local/lib/python3.8/site-packages/dbus_next/message_bus.py", line 621, in _on_message
    self._process_message(msg)
  File "/home/sami/.local/lib/python3.8/site-packages/dbus_next/message_bus.py", line 712, in _process_message
    handler(msg, send_reply)
  File "/home/sami/.local/lib/python3.8/site-packages/dbus_next/message_bus.py", line 774, in _default_introspect_handler
    introspection = self._introspect_export_path(msg.path).tostring()
  File "/home/sami/.local/lib/python3.8/site-packages/dbus_next/message_bus.py", line 506, in _introspect_export_path
    node.interfaces.append(interface.introspect())
  File "/home/sami/.local/lib/python3.8/site-packages/dbus_next/service.py", line 389, in introspect
    return intr.Interface(self.name,
  File "/home/sami/.local/lib/python3.8/site-packages/dbus_next/introspection.py", line 309, in __init__
    assert_interface_name_valid(name)
  File "/home/sami/.local/lib/python3.8/site-packages/dbus_next/validators.py", line 168, in assert_interface_name_valid
    raise InvalidInterfaceNameError(name)
dbus_next.errors.InvalidInterfaceNameError: invalid interface name: editai

[2023-03-25 04:10:42,886][root][ERROR] - got unexpected error processing a message: invalid interface name: editai.
Traceback (most recent call last):
  File "/home/sami/.local/lib/python3.8/site-packages/dbus_next/message_bus.py", line 621, in _on_message
    self._process_message(msg)
  File "/home/sami/.local/lib/python3.8/site-packages/dbus_next/message_bus.py", line 712, in _process_message
    handler(msg, send_reply)
  File "/home/sami/.local/lib/python3.8/site-packages/dbus_next/message_bus.py", line 774, in _default_introspect_handler
    introspection = self._introspect_export_path(msg.path).tostring()
  File "/home/sami/.local/lib/python3.8/site-packages/dbus_next/message_bus.py", line 506, in _introspect_export_path
    node.interfaces.append(interface.introspect())
  File "/home/sami/.local/lib/python3.8/site-packages/dbus_next/service.py", line 389, in introspect
    return intr.Interface(self.name,
  File "/home/sami/.local/lib/python3.8/site-packages/dbus_next/introspection.py", line 309, in __init__
    assert_interface_name_valid(name)
  File "/home/sami/.local/lib/python3.8/site-packages/dbus_next/validators.py", line 168, in assert_interface_name_valid
    raise InvalidInterfaceNameError(name)
dbus_next.errors.InvalidInterfaceNameError: invalid interface name: editai

[2023-03-25 04:11:08,596][root][ERROR] - got unexpected error processing a message: invalid interface name: editai.
Traceback (most recent call last):
  File "/home/sami/.local/lib/python3.8/site-packages/dbus_next/message_bus.py", line 621, in _on_message
    self._process_message(msg)
  File "/home/sami/.local/lib/python3.8/site-packages/dbus_next/message_bus.py", line 712, in _process_message
    handler(msg, send_reply)
  File "/home/sami/.local/lib/python3.8/site-packages/dbus_next/message_bus.py", line 774, in _default_introspect_handler
    introspection = self._introspect_export_path(msg.path).tostring()
  File "/home/sami/.local/lib/python3.8/site-packages/dbus_next/message_bus.py", line 506, in _introspect_export_path
    node.interfaces.append(interface.introspect())
  File "/home/sami/.local/lib/python3.8/site-packages/dbus_next/service.py", line 389, in introspect
    return intr.Interface(self.name,
  File "/home/sami/.local/lib/python3.8/site-packages/dbus_next/introspection.py", line 309, in __init__
    assert_interface_name_valid(name)
  File "/home/sami/.local/lib/python3.8/site-packages/dbus_next/validators.py", line 168, in assert_interface_name_valid
    raise InvalidInterfaceNameError(name)
dbus_next.errors.InvalidInterfaceNameError: invalid interface name: editai

